<?xml version="1.0"?>
<robot xmlns:xacro="http://www.ros.org/wiki/xacro" name="arm">

<xacro:property name="arm" value="$(find homework2)/config/arm.yaml" />
<xacro:property name="dictionary" value="${load_yaml(arm)}"/>
<xacro:property name="L1" value="${dictionary['L1']}"/>
<xacro:property name="L2" value="${dictionary['L2']}"/>   


<link name="base_link">
    <visual>
        <origin rpy="0 0 0" xyz="0 0 0" />
        <geometry>
          <cylinder radius="0.1" length="0.1" />
        </geometry>
        <material name="blue">
            <color rgba="0 0 1 1" />
        </material>
    </visual>
</link>

<joint name="joint1" type="continuous">
    <axis xyz="0 0 1" />
    <limit effort="1000.0" velocity="0.5" />
    <origin rpy="0 0 0" xyz="0 0 0.05" />
    <parent link="base_link" />
    <child link="link1" />
</joint>

<link name="link1">
    <visual>
        <origin rpy="${pi/4} ${pi/2} ${pi/4}" xyz="${L1/2} 0 0" />
        <geometry>
        <cylinder radius="0.1" length="${L1}" />
        </geometry>
        <material name="red">
            <color rgba="1 0 0 1" />
        </material>
    </visual>
</link>

<joint name="joint2" type="continuous">
    <axis xyz="0 0 1" />
    <limit effort="1000.0"  velocity="0.5" />
    <origin rpy="0 0 0" xyz="${L1} 0 0" />
    <parent link="link1" />
    <child link="link2" />
</joint>

<link name="link2">
    <visual>
        <origin rpy="0 ${pi/2} 0" xyz="${L2/2} 0 0" />
        <geometry>
        <cylinder radius="0.1" length="${L2}" />
        </geometry>
        <material name="green">
            <color rgba="0 1 0 1" />
        </material>
      </visual>
</link>

<joint name="joint3" type="fixed">
    <axis xyz="0 0 1" />
    <limit effort="1000.0"  velocity="0.5" />
    <origin rpy="0 0 0" xyz="${L2} 0 0" />
    <parent link="link2" />
    <child link="link3" />
</joint>

<link name="link3">
    <visual>
        <origin rpy="0 ${pi/2} 0" xyz="${1/2} 0 0" />
        <geometry>
        <cylinder radius="0.1" length="0.1" />
        </geometry>
        <material name="transparent">
            <color rgba="1 1 1 0" />
        </material>
      </visual>
</link>

</robot>
